Workbook

Sheet 工作表2
A1: 2500004214 | B1: NRND IC VOL REF ADJ 2.495V 100mA 1% | C1: TL431ACLPM
A2: 2500005303 | B2: NRND IC REGU 5V 100mA 5% SOIC-8P SMD | C2: UA78L05ACDR
A3: 2500050014 | B3: IC VOL REF 2.5V 15mA 1% SOT-23-3P SMD | C3: LM4040D25IDBZR
A4: 2500050311 | B4: IC VOL REF 5V 15mA 0.5% SOT-23-3P SMD | C4: LM4040CIM3X-5.0/NOPB
A5: 2500050314 | B5: IC VOL REF 5V 15mA 0.5% SOT-23-3P SMD | C5: LM4040C50IDBZR
A6: 2500050511 | B6: IC VOL REF 5V 15mA 0.2% SOT-23-3P SMD | C6: LM4040BIM3X-5.0/NOPB
A7: 2500050814 | B7: IC VOL REF 2.5V 25mA 0.5% SOT-23-3P SMD | C7: LM4040C25IDBZR
A8: 2500060714 | B8: IC VOL REF ADJ 2.495V 100mA 1% SOT-89-3P | C8: TL431AIPK
A9: 2500102111 | B9: IC REGU 5V 0.1A 0.5% SO-8P SMD | C9: LP2951ACMX/NOPB
A10: 2500102614 | B10: IC REGU 5V 100mA 0.5% SOIC-8P SMD | C10: LP2951-50DR
A11: 2500142914 | B11: IC VOL REF ADJ 1.24V 15mA 1% SOT-23-5P | C11: TLV431AIDBVR
A12: 2500144414 | B12: IC REGU 12V 0.1A 5% SOT-89-3P SMD | C12: UA78L12ACPK
... A351: 2633036208 | B351: IC ASIC MCU HLQFP-176P SMD | C351: TMS320F2837HDPTPT

Sheet Sheet3
A3: 差異説明 | B3: Vedor P/N | C3: PCN 單號(規格） | D3: Sum of DSW1 | E3: Sum of IMW1 | F3: Sum of PSW1 | G3: Sum of TPW1 | H3: Sum of UPW1
A4: HVP-ACDC | B4: UC2842AD8TR | C4: (blank) | E4: 185000
B5: UC2843ADTR | C5: (blank)
B6: UC2843AQD8RQ1 | C6: PCN10H21020250314053135
B7: UC2843D8TR | C7: (blank) | F7: 12500
B8: UC2844ADTR | C8: N
B9: UC2844AQD8R | C9: 否 | E9: 60000 | G9: 2500 | H9: 5000
B10: UC2845AD8TR | C10: (blank) | H10: 17500
B11: UC2845AQD8R | C11: PCN10H21020250314053135 | G11: 29500
B12: UC3845AD8TR | C12: (blank) | G12: 5000 | H12: 420000
B13: UCC28065DR | C13: N
B14: UCC28951QPWRQ1 | C14: (blank)
B15: UCC2895PWTR | C15: PCN10H21020250529091608 PCN10H21020250317102220
A16: HVP-DBB | B16: ISO5452DWR | C16: PCN10H21020241118055211 | E16: 148000
B17: ISO5852SDWR | C17: PCN10H21020250314113012 PCN10H21020241226120620
B18: SN6505BDBVR | C18: (blank) | E18: 7780 | H18: 3000
B19: UCC21220ADR | C19: PCN10H21020241226041235 | G19: 130000
B20: UCC21220DR | C20: PCN10H21020260407161104 | G20: 7500
B21: UCC21222DR | C21: PCN10H21020260407161104 | G21: 7500
B22: UCC21520ADWR | C22: (blank) | G22: 120000
B23: UCC21520DWR | C23: (blank) | G23: 134000 | H23: 70000
B24: UCC21530DWKR | C24: PCN10H21020241226041235 | H24: 16000
B25: UCC27211AQDDARQ1 | C25: (blank) | G25: 402500
B26: UCC27282DRCR | C26: PCN10H21020220610044559-Y
B27: UCC27322DR | C27: PCN10H21020240221114349 | G27: 5000
B28: UCC27424DGNR | C28: PCN10H21020240221114349 | G28: 31500
B29: UCC27424DR | C29: (blank) | G29: 77500 | H29: 17500
B30: UCC27425DR | C30: PCN10H21020240221114349-Y | H30: 50
B31: UCC27524ADGNR | C31: PCN10H21020250106100555 | G31: 10000
B32: UCC27524DGNR | C32: PCN10H21020250106100555 | G32: 2500 | H32: 2500
B33: UCC27524DR | C33: (blank) | G33: 162500 | H33: 2500
B34: UCC27525DR | C34: (blank) | G34: 100000
B35: UCC5350MCDR | C35: PCN10H21020250317034614 | G35: 2500
B36: UCC5390SCDR | C36: PCN10H21020250317034614 | G36: 2500 | H36: 17500
B39: 20250528000
B40: 20221215001
B41: 20220601000

Sheet WK 0731
A1: DELTA PN | B1: Vedor P/N | C1: PCN 單號(規格） | D1: Sum of DSW1 | E1: Sum of IMW1 | F1: Sum of PSW1 | G1: Sum of TPW1 | H1: Sum of UPW1 | I1: Comparison | J1: TI PCN# | K1: TI PCN# 2 | L1: TI PCN# 3 | M1: Post-PCN 1st DC | N1: Comments
A2: =VLOOKUP(B:B,匯總表!A:C,3,FALSE) -> 2510569314 | B2: TPS5410DR | C2: PCN10H21020250917125432 | G2: 82500 | H2: 2500 | I2: RE PCN影响确认_TPS5430DDAR2510455714_TPW1 | J2: 20231219004 | K2: 20260427001 | L2: 20240424000
A3: =VLOOKUP(B:B,匯總表!A:C,3,FALSE) -> 2510569814 | B3: TPS5420DR | C3: PCN10H21020250917125432 PCN10H21020250901144202 PCN10H21020250318114142 | G3: 17000 | I3: RE PCN影响确认_TPS5430DDAR2510455714_TPW1 | J3: 20231219004 | K3: 20260427001 | L3: 20240424000
A4: =VLOOKUP(B:B,匯總表!A:C,3,FALSE) -> 2510455714 | B4: TPS5430DDAR | C4: PCN10H21020250318114142 PCN10H21020250901144202 PCN10H21020250917125432 | I4: RE PCN影响确认_TPS5430DDAR2510455714_TPW1 | J4: 20231219004 | K4: 20260427001 | L4: 20240424000
A5: =VLOOKUP(B:B,匯總表!A:C,3,FALSE) -> 2510455714 | B5: TPS5430DDAR | C5: PCN10H21020250901144202 PCN10H21020250318114142 | E5: 12500 | G5: 122500 | H5: 5000 | I5: RE PCN影响确认_TPS5430DDAR2510455714_TPW1 | J5: 20231219004 | K5: 20260427001 | L5: 20240424000
A6: =VLOOKUP(B:B,匯總表!A:C,3,FALSE) -> 2520124114 | B6: LM224ADR | C6: PCN10H21020241231051413 | G6: 7500 | I6: Part Number -Differencecomparisontable_risk assessment table_LM2902KAVQPWR | J6: 2.0241119e+10
A7: =VLOOKUP(B:B,匯總表!A:C,3,FALSE) -> 2520124014 | B7: LM224DR | C7: 否 | E7: 85000 | I7: Part Number -Differencecomparisontable_risk assessment table_LM2902KAVQPWR | J7: 2.0241119e+10
A8: =VLOOKUP(B:B,匯總表!A:C,3,FALSE) -> 2520036014 | B8: LM2902DR | C8: PCN10H21020241231051413 | G8: 5000 | I8: Part Number -Differencecomparisontable_risk assessment table_LM2902KAVQPWR | J8: 2.0241119e+10
A9: =VLOOKUP(B:B,匯總表!A:C,3,FALSE) -> 2520036614 | B9: LM2902KAVQPWR | C9: (blank) | G9: 18000 | I9: Part Number -Differencecomparisontable_risk assessment table_LM2902KAVQPWR | J9: 2.0241119e+10
A10: =VLOOKUP(B:B,匯總表!A:C,3,FALSE) -> 2520036614M | B10: LM2902KAVQPWRQ1 | C10: (blank) | I10: Part Number -Differencecomparisontable_risk assessment table_LM2902KAVQPWR | J10: 2.0241119e+10
A11: =VLOOKUP(B:B,匯總表!A:C,3,FALSE) -> 2522014814 | B11: LM2902KVQDR | C11: (blank) | I11: Part Number -Differencecomparisontable_risk assessment table_LM2902KAVQPWR | J11: 2.0241119e+10
A12: =VLOOKUP(B:B,匯總表!A:C,3,FALSE) -> 2520036314 | B12: LM2902PWR | C12: (blank) | G12: 212000 | I12: Part Number -Differencecomparisontable_risk assessment table_LM2902KAVQPWR | J12: 2.0241119e+10
A13: =VLOOKUP(B:B,匯總表!A:C,3,FALSE) -> 2520016214 | B13: LM324ADR | C13: (blank) | H13: 15000 | I13: Part Number -Differencecomparisontable_risk assessment table_LM2902KAVQPWR | J13: 2.0241119e+10
A14: =VLOOKUP(B:B,匯總表!A:C,3,FALSE) -> 2520016414 | B14: LM324DR | C14: PCN10H21020241231051413 | H14: 5000 | I14: Part Number -Differencecomparisontable_risk assessment table_LM2902KAVQPWR | J14: 2.0241119e+10
A15: =VLOOKUP(B:B,匯總表!A:C,3,FALSE) -> 2520016014 | B15: LM324N | C15: PCN10H21020250106035959 PCN10H21020241231051413 PCN10H21020241231044210 PCN10H21020241231050033 | H15: 2000 | I15: Part Number -Differencecomparisontable_risk assessment table_LM2902KAVQPWR | J15: 2.0241119e+10
A16: =VLOOKUP(B:B,匯總表!A:C,3,FALSE) -> 2540709608 | B16: UCC21220ADR | C16: PCN10H21020241226041235 | G16: 130000 | I16: Megatron and Skywarp PCN update - V3 | J16: 20241112000 | K16: 20241209000 | L16: 20240405000 | M16: 2543 | N16: Pre-PCN needs to move to SN21220ADR
A17: =VLOOKUP(B:B,匯總表!A:C,3,FALSE) -> 2540597808 | B17: UCC21220DR | C17: PCN10H21020260407161104 | G17: 7500 | I17: Megatron and Skywarp PCN update - V3 | J17: 20241112000 | K17: 20241209000 | L17: 20240405000 | M17: no PCN | N17: Confirmed to hold PCN for UCC21220DR (non-A) and UCC21222DR
A18: =VLOOKUP(B:B,匯總表!A:C,3,FALSE) -> 2540739508 | B18: UCC21222DR | C18: PCN10H21020260407161104 | G18: 7500 | I18: Megatron and Skywarp PCN update - V3 | J18: 20241112000 | K18: 20241209000 | L18: 20240405000 | M18: no PCN | N18: Confirmed to hold PCN for UCC21220DR (non-A) and UCC21222DR
A19: =VLOOKUP(B:B,匯總表!A:C,3,FALSE) -> 2540723308 | B19: UCC21520ADWR | C19: (blank) | G19: 120000 | I19: Megatron and Skywarp PCN update - V3 | J19: 20241112000 | K19: 20241209000 | L19: 20240405000 | N19: UCC21520DWR, UCC21530, UCC21540 no system impact
A20: =VLOOKUP(B:B,匯總表!A:C,3,FALSE) -> 2540715608 | B20: UCC21520DWR | C20: (blank) | G20: 134000 | H20: 70000 | I20: Megatron and Skywarp PCN update - V3 | J20: 20241112000 | K20: 20241209000 | L20: 20240405000 | N20: UCC21520DWR, UCC21530, UCC21540 no system impact
A21: =VLOOKUP(B:B,匯總表!A:C,3,FALSE) -> 2540764808 | B21: UCC21530DWKR | C21: PCN10H21020241226041235 | H21: 16000 | I21: Megatron and Skywarp PCN update - V3 | J21: 20241112000 | K21: 20241209000 | L21: 20240405000 | N21: UCC21520DWR, UCC21530, UCC21540 no system impact
A22: =VLOOKUP(B:B,匯總表!A:C,3,FALSE) -> 2600092408 | B22: SN74LVC08ADR | C22: PCN10H21020250326051746 | G22: 470 | H22: 552500 | I22: Delta_PCN_Logics (260106) | J22: 20240730002 | K22: 20250306000
A23: =VLOOKUP(B:B,匯總表!A:C,3,FALSE) -> 2600077908 | B23: SN74LVC32ADR | C23: PCN10H21020250326051746 PCN10H21020250325042300 | G23: 550 | H23: 20000 | I23: Delta_PCN_Logics (260106) | J23: 20240730002 | K23: 20250306000
A24: =VLOOKUP(B:B,匯總表!A:C,3,FALSE) -> #N/A | B24: SN74LVC125ADBR | C24: (blank) | I24: Delta_PCN_Logics (260106) | J24: 20240730002 | K24: 20250306000
A25: =VLOOKUP(B:B,匯總表!A:C,3,FALSE) -> 2600116608 | B25: SN74LVC244APWR | C25: (blank) | E25: 622000 | I25: Delta_PCN_Logics (260106) | J25: 20240730002 | K25: 20250306000
A26: =VLOOKUP(B:B,匯總表!A:C,3,FALSE) -> 2600354608 | B26: SN74LVC244ARGYR | C26: (blank) | E26: 36000 | I26: Delta_PCN_Logics (260106) | J26: 20240730002 | K26: 20250306000
A27: =VLOOKUP(B:B,匯總表!A:C,3,FALSE) -> 2600126408 | B27: SN74AHCT1G04DBVR | C27: (blank) | E27: 387000 | I27: Delta_PCN_Logics (260106) | J27: 20240730002 | K27: 20250306000
A28: =VLOOKUP(B:B,匯總表!A:C,3,FALSE) -> 2600212208 | B28: SN74ACT240PWR | C28: (blank) | E28: 156000 | I28: Delta_PCN_Logics (260106) | J28: 20240730002 | K28: 20250306000
A29: =VLOOKUP(B:B,匯總表!A:C,3,FALSE) -> 2610290108 | B29: SN74AHC1G08DBVR | C29: PCN10H21020250325033359 | G29: 12000 | I29: Delta_PCN_Logics (260106) | J29: 20240730002 | K29: 20250306000
A30: =VLOOKUP(B:B,匯總表!A:C,3,FALSE) -> 2600212208 | B30: SN74ACT240PWR | C30: (blank) | E30: 156000 | I30: SN74AHC1G08DBVR Difference comparison table Risk Assessment | J30: 20231219000
A31: =VLOOKUP(B:B,匯總表!A:C,3,FALSE) -> 2610290108 | B31: SN74AHC1G08DBVR | C31: PCN10H21020250325033359 | G31: 12000 | I31: SN74AHC1G08DBVR Difference comparison table Risk Assessment | J31: 20231219000
A32: =VLOOKUP(B:B,匯總表!A:C,3,FALSE) -> 2600259408 | B32: SN74AHC1G09DBVR | C32: PCN10H21020240226113556 | E32: 3000 | I32: SN74AHC1G08DBVR Difference comparison table Risk Assessment | J32: 20231219000
A33: =VLOOKUP(B:B,匯總表!A:C,3,FALSE) -> 2600037808 | B33: SN74AHC1G126DBVR | C33: (blank) | E33: 48000 | I33: SN74AHC1G08DBVR Difference comparison table Risk Assessment | J33: 20231219000
A34: =VLOOKUP(B:B,匯總表!A:C,3,FALSE) -> 2600157208 | B34: SN74AHC1G86DBVR | C34: (blank) | E34: 18000 | I34: SN74AHC1G08DBVR Difference comparison table Risk Assessment | J34: 20231219000
A35: =VLOOKUP(B:B,匯總表!A:C,3,FALSE) -> 2600126408 | B35: SN74AHCT1G04DBVR | C35: (blank) | E35: 387000 | I35: SN74AHC1G08DBVR Difference comparison table Risk Assessment | J35: 20231219000
A36: =VLOOKUP(B:B,匯總表!A:C,3,FALSE) -> 2600029608 | B36: SN74AHCT1G08DBVR | C36: PCN10H21020240226113556 | E36: 3000 | I36: SN74AHC1G08DBVR Difference comparison table Risk Assessment | J36: 20231219000
A37: =VLOOKUP(B:B,匯總表!A:C,3,FALSE) -> 2600178008 | B37: SN65176BDR | C37: (blank) | E37: 405000 | G37: 10600 | H37: 7500 | I37: SN65176BDR-Differencecomparisontable_risk assessment table | J37: 20210811000 | K37: 20211123004 | L37: 20211229001
A38: =VLOOKUP(B:B,匯總表!A:C,3,FALSE) -> 2520041214 | B38: OP07CDR | C38: (blank) | G38: 2500 | I38: Differencecomparisontable_risk assessment table_OP07CDR, OP07C Redbull Differences - Input Offset Null (002) | J38: 20231031008
A39: =VLOOKUP(B:B,匯總表!A:C,3,FALSE) -> 2600135808 | B39: SN74LVC1G04DCKR | C39: (blank) | D39: 9000 | E39: 219000 | G39: 15250 | I39: SN74LVC1G04DCKR Delta Risk Assessment(0514) | J39: 20251104000 | K39: 20260313003
A40: =VLOOKUP(B:B,匯總表!A:C,3,FALSE) -> 2600005908 | B40: SN74LVC1G06DCKR | C40: (blank) | E40: 12000 | I40: SN74LVC1G04DCKR Delta Risk Assessment(0514) | J40: 20251104000 | K40: 20260313003
...

Sheet Sheet1
A1: Vendor PN | B1: Risk Assessment File | C1: File Location | D1: Match
A2: ADS8684IDBTR | B2: 20250630000.xlsx | C2: C:/Users/a1253695/OneDrive - TEXAS INSTRUMENTS/Desktop/To Claude/PCN risk assesment table\DELTA Risk assessment files from BU\DCC\20250630000.xlsx | D2: YES
A3: ISO124U/1K | B3: 20250319003.xlsx | C3: C:/Users/a1253695/OneDrive - TEXAS INSTRUMENTS/Desktop/To Claude/PCN risk assesment table\DELTA Risk assessment files from BU\DCC\20250319003.xlsx | D3: YES
A4: LM224DR | B4: RE_ URGENT LM224DR PCN in Delta - Production Hold Due to PCN#20241119003_1(1) Material Discrepancies.msg | C4: C:/Users/a1253695/OneDrive - TEXAS INSTRUMENTS/Desktop/To Claude/PCN risk assesment table\20241119003.1\RE_ URGENT LM224DR PCN in Delta - Production Hold Due to PCN#20241119003_1(1) Material Discrepancies.msg | D4: YES
A5: LM2902DR | B5: Number -Differencecomparisontable_risk assessment table_LM2902DR.xlsx | C5: C:/Users/a1253695/OneDrive - TEXAS INSTRUMENTS/Desktop/To Claude/PCN risk assesment table\2520036014\Number -Differencecomparisontable_risk assessment table_LM2902DR.xlsx | D5: YES
A6: LM2902KAVQPWR | B6: Part Number -Differencecomparisontable_risk assessment table_LM2902KAVQPWR.xlsx | C6: C:/Users/a1253695/OneDrive - TEXAS INSTRUMENTS/Desktop/To Claude/PCN risk assesment table\20241119003.1\Part Number -Differencecomparisontable_risk assessment table_LM2902KAVQPWR.xlsx | D6: YES
A7: LP2985A-33DBVR | B7: Delta Risk Assessment LP2985A-33DBVR.xlsx | C7: C:/Users/a1253695/OneDrive - TEXAS INSTRUMENTS/Desktop/To Claude/PCN risk assesment table\20250919000\Delta Risk Assessment LP2985A-33DBVR.xlsx | D7: YES
A8: OP07CDR | B8: Differencecomparisontable_risk assessment table_OP07CDR.xlsx | C8: C:/Users/a1253695/OneDrive - TEXAS INSTRUMENTS/Desktop/To Claude/PCN risk assesment table\2520041214\Differencecomparisontable_risk assessment table_OP07CDR.xlsx | D8: YES
A9: OPA4991IPWR | B9: OPA4991IPWR -Differencecomparisontable_risk assessment table.XLSX | C9: C:/Users/a1253695/OneDrive - TEXAS INSTRUMENTS/Desktop/To Claude/PCN risk assesment table\20221216011\OPA4991IPWR -Differencecomparisontable_risk assessment table.XLSX | D9: YES
A10: SN74ACT244PWR | B10: Differencecomparisontable_risk assessment table.xlsx | C10: C:/Users/a1253695/OneDrive - TEXAS INSTRUMENTS/Desktop/To Claude/PCN risk assesment table\20250402002\Differencecomparisontable_risk assessment table.xlsx | D10: YES
A11: SN74AHC1G04DCKR | B11: Differencecomparisontable_risk assessment table.xlsx | C11: C:/Users/a1253695/OneDrive - TEXAS INSTRUMENTS/Desktop/To Claude/PCN risk assesment table\20250402002\Differencecomparisontable_risk assessment table.xlsx | D11: YES
A12: SN74LVC1G04DCKR | B12: SN74LVC1G04DCKR Delta Risk Assessment(0514).xlsx | C12: C:/Users/a1253695/OneDrive - TEXAS INSTRUMENTS/Desktop/To Claude/PCN risk assesment table\20260313003.0\SN74LVC1G04DCKR Delta Risk Assessment(0514).xlsx | D12: YES
... A15: TPS5430DDAR | B15: RE TPS5430DDAR FUT測試不良100% (RP240 TI Chip ISSUE-Hold Shipment).msg | C15: C:/Users/a1253695/OneDrive - TEXAS INSTRUMENTS/Desktop/To Claude/PCN risk assesment table\DELTA Risk assessment files from BU\TPS5430 TPS5430 ENA Pin Design_202602\RE TPS5430DDAR FUT測試不良100% (RP240 TI Chip ISSUE-Hold Shipment).msg | D15: YES

Sheet Sheet4

Sheet 匯總表
A1: Vedor P/N | B1: SQE | C1: 列標籤 | D1: Vedor P/N | E1: TI 回復是否有差異 | F1: 切换DC | G1: 首次出货时间 | H1: 差異説明 | I1: DSW1 | J1: IMW1 | K1: PSW1 | L1: TPW1 | M1: UPW1 | N1: 總計 | O1: 系統是否有PCN | P1: PCN 申請筆數（2024-2026） | Q1: 次數 | R1: YN修改規格 | S1: YN有設計變更 | T1: PCN 單號(規格） | U1: PCN 單號(設計） | V1: 變更内容 | X1: PCN# | Y1: risk assessment match?
A2: INA226AIDGSR | B2: XUEMEI | C2: 2540558408 | D2: =VLOOKUP(C2,工作表2!A:C,3,0) -> INA226AIDGSR | H2: =VLOOKUP(D:D,[1]results!$A:$AE,31,FALSE) -> SENSING-CS | O2: Y | P2: PCN10H21020251222104013-Y PCN10H21020250718110110-N PCN10H21020241115034047-N PCN10H21020240704121737-N | Q2: 4 | R2: Y | S2: Y | T2: PCN10H21020251222104013-Y PCN10H21020250718110110-Y | U2: PCN10H21020251222104013-Y | V2: RFAB,Process change, Site change, Material change, Design change/Electrical Specification | W2: SN74LVC1G3157DCKR | X2: 20151215003A | Y2: =VLOOKUP(D:D,Sheet1!A:D,4,FALSE) -> #N/A
A3: TRSF3232EIPWR | B3: DAISY | C3: 2540177408 | D3: =VLOOKUP(C3,工作表2!A:C,3,0) -> TRSF3232EIPWR | H3: =VLOOKUP(D:D,[1]results!$A:$AE,31,FALSE) -> INT-TRX | L3: 10000 | M3: 30000 | N3: 40000 | O3: Y | P3: PCN10H21020250612101508 PCN10H21020250513051742 PCN10H21020241212051217 PCN10H21020241021053404 | Q3: 4 | R3: Y | S3: Y | T3: PCN10H21020241021053404 | U3: PCN10H21020241021053404 | V3: PCN10H21020250612101508:Process change, Site change, Material change;Qualification of additional Assembly sites for select TSSOP devices PCN10H21020250513051742:Process change, Site change, Material change;Qualification of additional Assembly sites for select TSSOP devices PCN10H21020241212051217:Process change;Marking Standardization for Select Devices PCN10H21020241021053404:Process change, Site change, Material change, Design change;Qualification of new Fab site (RFAB) using qualified Process Technology, Die Revision, Datasheet update and additional Assembly site/BOM options for select devices | W3: TPS65216D0RSLR | X3: 20190411001.1 | Y3: =VLOOKUP(D:D,Sheet1!A:D,4,FALSE) -> #N/A
A4: MAX3232CDR | B4: JINGJING | C4: 2540176108 | D4: =VLOOKUP(C4,工作表2!A:C,3,0) -> MAX3232CDR | H4: =VLOOKUP(D:D,[1]results!$A:$AE,31,FALSE) -> INT-TRX | K4: 2500 | M4: 7500 | N4: 10000 | O4: Y | P4: PCN10H21020241021053404 PCN10H21020241118085631 PCN10H21020241202012940 | Q4: 3 | R4: Y | S4: Y | T4: PCN10H21020241021053404 | U4: PCN10H21020241021053404 | V4: PCN10H21020241021053404:Process change, Site change, Material change, Design change;Qualification of new Fab site (RFAB) using qualified Process Technology, Die Revision, Datasheet update and additional Assembly site/BOM options for select devices PCN10H21020241118085631:Process change;Marking Standardization for Select Devices PCN10H21020241202012940:Site change, Material change;Qualification of ASESH as an Additional Assembly Site for Select Devices in the 8/14/16 pin SOIC (D) packages using NiPdAuAg Leadframe | W4: 1 2540176108 MAX3232CDR 2 2540176308 MAX3232CPWR 3 2540177408 TRSF3232EIPWR 4 2540485808 MAX3232EIPWR 5 2540593108 TRS3232EIDR 6 2540786208 SN65C3232EPWR | X4: 20210625000.1 | Y4: =VLOOKUP(D:D,Sheet1!A:D,4,FALSE) -> #N/A
A5: TLC555IDR | B5: JINGJING | C5: 2510352514 | D5: =VLOOKUP(C5,工作表2!A:C,3,0) -> TLC555IDR | H5: =VLOOKUP(D:D,[1]results!$A:$AE,31,FALSE) -> LAMPS-LVAC | M5: 10000 | N5: 10000 | O5: Y | P5: PCN10H21020240218094418 | Q5: 1 | R5: Y | S5: Y | T5: PCN10H21020240218094418 | U5: PCN10H21020240218094418 | V5: PCN10H21020240218094418Process change, Site change, Material change, Design change：Qualification of RFAB using qualified Process Technology, Die Revision, Datasheet update and additional Assembly Site/BOM options for select devices | W5: 1 2540176108 MAX3232CDR 2 2540176308 MAX3232CPWR 3 2540177408 TRSF3232EIPWR 4 2540485808 MAX3232EIPWR 5 2540593108 TRS3232EIDR 6 2540786208 SN65C3232EPWR | X5: 20210625000.1 | Y5: =VLOOKUP(D:D,Sheet1!A:D,4,FALSE) -> #N/A
A6: LM2901DR | B6: JINGJING | C6: 2520050014 | D6: =VLOOKUP(C6,工作表2!A:C,3,0) -> LM2901DR | H6: =VLOOKUP(D:D,[1]results!$A:$AE,31,FALSE) -> LAMPS-LVAC | L6: 10000 | N6: 10000 | O6: Y | P6: PCN10H21020250724103020 PCN10H21020241202012940 PCN10H21020241118085631 PCN10H21020240208105701 | Q6: 4 | R6: Y | S6: N | T6: PCN10H21020250724103020 | V6: PCN10H21020250724103020:Process change;Datasheet for LM3302, LM339B, LM2901B, LM339, LM239, LM139, LM2901 PCN10H21020241118085631:Process change;Marking Standardization for Select Devices PCN10H21020241202012940:Site change, Material change;Qualification of ASESH as an Additional Assembly Site for Select Devices in the 8/14/16 pin SOIC (D) packages using NiPdAuAg Leadframe | W6: 1 2540176108 MAX3232CDR 2 2540176308 MAX3232CPWR 3 2540177408 TRSF3232EIPWR 4 2540485808 MAX3232EIPWR 5 2540593108 TRS3232EIDR 6 2540786208 SN65C3232EPWR | X6: 20210625000.1 | Y6: =VLOOKUP(D:D,Sheet1!A:D,4,FALSE) -> #N/A
A7: LP2985A-18DBVR | B7: JINGJING | C7: 2500235714 | D7: =VLOOKUP(C7,工作表2!A:C,3,0) -> LP2985A-18DBVR | H7: =VLOOKUP(D:D,[1]results!$A:$AE,31,FALSE) -> LP-MWL | L7: 6000 | N7: 6000 | O7: Y | P7: PCN10H21020240911110514 PCN10H21020240923100040 PCN10H21020241209052044 PCN10H21020250506044328 | Q7: 4 | R7: Y | S7: Y | T7: PCN10H21020240911110514 | U7: PCN10H21020240911110514 | V7: PCN10H21020240911110514:Process change, Site change, Material change, Design change;Qualification of RFAB Wafer Fab site using qualified Process Technology, Die Revision and additional Assembly site/BOM options for select devices PCN10H21020250506044328:Process change:Pin one Device symbolization update for Select SOT Devices PCN10H21020241209052044:Process change;Pin one Device symbolization update for Select SOT Devices | W7: 1 2540176108 MAX3232CDR 2 2540176308 MAX3232CPWR 3 2540177408 TRSF3232EIPWR 4 2540485808 MAX3232EIPWR 5 2540593108 TRS3232EIDR 6 2540786208 SN65C3232EPWR | X7: 20210625000.1 | Y7: =VLOOKUP(D:D,Sheet1!A:D,4,FALSE) -> #N/A
A8: UA78L12ACPK | B8: JINGJING | C8: 2500144414 | D8: =VLOOKUP(C8,工作表2!A:C,3,0) -> UA78L12ACPK | H8: =VLOOKUP(D:D,[1]results!$A:$AE,31,FALSE) -> LP-MWL | J8: 4000 | N8: 4000 | O8: Y | P8: PCN10H21020240206113453 PCN10H21020240206112156 PCN10H21020241119050428 PCN10H21020241209052044 PCN10H21020250506044328 | Q8: 5 | R8: Y | S8: Y | T8: PCN10H21020240206113453 | U8: PCN10H21020240206113453 | V8: PCN10H21020240206113453:Process change, Site change, Material change, Design change;Qualification of additional Fab site (RFAB) using qualified Process Technology and additional BOM options for select devices (The information we uploaded in the PCN10H21020240206112156 is incorrect, please reject and ignore it. Thank you.) PCN10H21020250506044328:Process change:Pin one Device symbolization update for Select SOT Devices PCN10H21020241209052044:Process change;Pin one Device symbolization update for Select SOT Devices | W8: 1 2540176108 MAX3232CDR 2 2540176308 MAX3232CPWR 3 2540177408 TRSF3232EIPWR 4 2540485808 MAX3232EIPWR 5 2540593108 TRS3232EIDR 6 2540786208 SN65C3232EPWR | X8: 20210625000.1 | Y8: =VLOOKUP(D:D,Sheet1!A:D,4,FALSE) -> #N/A
A9: DP83867IRRGZR | B9: XUEMEI | C9: 2620244308 | D9: =VLOOKUP(C9,工作表2!A:C,3,0) -> DP83867IRRGZR | H9: =VLOOKUP(D:D,[1]results!$A:$AE,31,FALSE) -> DCC-ETHERNET | O9: Y | P9: PCN10H21020241204010710-N PCN10H21020250219102259-N | Q9: 2 | R9: Y | S9: N | T9: PCN10H21020241204010710-Y PCN10H21020250219102259-Y | V9: Electrical Specification | W9: SN65176BDR | X9: 20210811000.1 | Y9: =VLOOKUP(D:D,Sheet1!A:D,4,FALSE) -> #N/A
A10: SN74AHCT14PWR | B10: XUEMEI | C10: 2600088708 | D10: =VLOOKUP(C10,工作表2!A:C,3,0) -> SN74AHCT14PWR | H10: =VLOOKUP(D:D,[1]results!$A:$AE,31,FALSE) -> INT-LOGIC | O10: Y | P10: PCN10H21020241128062552-N PCN10H21020241121045047-Y PCN10H21020240206111052-Y | Q10: 3 | R10: N | S10: Y | T10: N | U10: PCN10H21020241121045047 | V10: RFAB ,Die Revision,Assembly site,Wafer Fab Materials/Wafer Fab Process | W10: 1 2600223208 CD74HC4094PWR 2 2600364608 CD74HC173PWR | X10: 20220628000.1(1) | Y10: =VLOOKUP(D:D,Sheet1!A:D,4,FALSE) -> #N/A
A11: UCC27282DRCR | B11: XUEMEI | C11: 2540614208 | D11: =VLOOKUP(C11,工作表2!A:C,3,0) -> UCC27282DRCR | H11: =VLOOKUP(D:D,[1]results!$A:$AE,31,FALSE) -> HVP-DBB | O11: Y | P11: PCN10H21020230213042553-N PCN10H21020231103104228-N PCN10H21020220610044559-N PCN10H21020250530034631-N | Q11: 4 | R11: N | S11: N | T11: PCN10H21020220610044559-Y | U11: N | V11: RFAB ,Wafer Fab Materials RFAB ,Electrical Specification,Wafer Fab Materials/Wafer Fab Process | W11: 1 2600081808 SN74LVC00APWR 2 2600092208 SN74LVC08APWR 3 2600103808 SN74LVC125APWR 4 2600147008 SN74LVC32APWR | X11: 20240514001.1 | Y11: =VLOOKUP(D:D,Sheet1!A:D,4,FALSE) -> #N/A
A12: UC2842AD8TR | B12: CHUNHUA | C12: 2510069214 | D12: =VLOOKUP(C12,工作表2!A:C,3,0) -> UC2842AD8TR | H12: =VLOOKUP(D:D,[1]results!$A:$AE,31,FALSE) -> HVP-ACDC | J12: 185000 | N12: 185000 | O12: Y | P12: PCN10H21020250220051144 PCN10H21020241231040349 | Q12: 2 | R12: N | S12: Y | U12: PCN10H21020241231040349 | V12: Process change, Site change, Material change, Design change;Qualification of RFAB using qualified Process Technology, Die Revision, & Assembly site (TI Mexico) & BOM options for select devices(group1) | W12: 1 2500172114 TL432BIDBZR 2 2500172114P TL432BIDBZR-P 3 2500278414 TL431AIDBZR 4 2500333214 TL431BCDBZR 5 2500333414 TL432AQDBZR 6 2500333814 TL432AIDBZR 7 2500395314 TL431BIDBZR 8 2500434114 TL431ACDBZR 9 2500434514 TL431AQDBZRG4 10 2500434614 TL432BCDBZR 11 2500478014 TL431BQDBZR 12 2500478314 TL432BQDBZR | X12: 20220909000.1 | Y12: =VLOOKUP(D:D,Sheet1!A:D,4,FALSE) -> #N/A
A13: ISO6721BDR | B13: CHUNHUA | C13: 2540796108 | D13: =VLOOKUP(C13,工作表2!A:C,3,0) -> ISO6721BDR | F13: 2421+5 | G13: 45517 | H13: =VLOOKUP(D:D,[1]results!$A:$AE,31,FALSE) -> INT-ISO | L13: 105000 | M13: 42000 | N13: 147000 | O13: Y | P13: PCN10H21020250328053731 PCN10H21020240809031513 | Q13: 2 | R13: N | S13: Y | U13: PCN10H21020250328053731 | V13: Qualification of RFAB as an additional Fab site option for select LBC8 devices | W13: 1 2500172114 TL432BIDBZR 2 2500172114P TL432BIDBZR-P 3 2500278414 TL431AIDBZR 4 2500333214 TL431BCDBZR 5 2500333414 TL432AQDBZR 6 2500333814 TL432AIDBZR 7 2500395314 TL431BIDBZR 8 2500434114 TL431ACDBZR 9 2500434514 TL431AQDBZRG4 10 2500434614 TL432BCDBZR 11 2500478014 TL431BQDBZR 12 2500478314 TL432BQDBZR | X13: 20220909000.1 | Y13: =VLOOKUP(D:D,Sheet1!A:D,4,FALSE) -> #N/A
A14: LMV331IDCKR | B14: XUEMEI | C14: 2520170114 | D14: =VLOOKUP(C14,工作表2!A:C,3,0) -> LMV331IDCKR | H14: =VLOOKUP(D:D,[1]results!$A:$AE,31,FALSE) -> LAMPS-LVAC | J14: 95 | N14: 95 | O14: Y | P14: PCN10H21020240627024619-Y PCN10H21020241209052044-N PCN10H21020241119121859-Y PCN10H21020250506044328-N | Q14: 4 | R14: Y | S14: Y | T14: N | U14: PCN10H21020240627024619-Y PCN10H21020241119121859-Y | V14: RFAB,Assembly Site/Materials.Test Site,Wafer Fab Site,Wafer Fab Material,PROCESS Assembly Materials/SITE/process/Test Site/Wafer Fab Materials/Design | W14: 1 2600088308 SN74LV14APWR 2 2600092808 SN74LV08APWR 3 2600147308 SN74LV32APWR | X14: 20220926000.1 | Y14: =VLOOKUP(D:D,Sheet1!A:D,4,FALSE) -> #N/A
A15: SN6505BDBVR | B15: DAISY | C15: 2540715808 | D15: =VLOOKUP(C15,工作表2!A:C,3,0) -> SN6505BDBVR | H15: =VLOOKUP(D:D,[1]results!$A:$AE,31,FALSE) -> HVP-DBB | J15: 7780 | M15: 3000 | N15: 10780 | O15: Y | P15: PCN10H21020250506044328 PCN10H21020250220042307 PCN10H21020241209052044 PCN10H21020230906111252 | Q15: 4 | R15: N | S15: Y | U15: PCN10H21020230906111252 | V15: PCN10H21020250506044328:Process change:Pin one Device symbolization update for Select SOT Devices PCN10H21020250220042307:LABEL/MARKING PCN10H21020241209052044:Process change;Pin one Device symbolization update for Select SOT Devices PCN10H21020230906111252:Qualification of additional Fab site (RFAB) and additional Assembly site (TIPI) for select LBC8LV devices | Y15: =VLOOKUP(D:D,Sheet1!A:D,4,FALSE) -> #N/A
A16: LM2904AVQPWRQ1 | B16: RAINIE | C16: 2520240414M | D16: =VLOOKUP(C16,工作表2!A:C,3,0) -> LM2904AVQPWRQ1 | H16: =VLOOKUP(D:D,[1]results!$A:$AE,31,FALSE) -> LAMPS-HVA | L16: 400 | N16: 400 | O16: Y | P16: PCN10H21020250617111214 | Q16: 1 | R16: Y | S16: Y | T16: PCN10H21020250617111214 | U16: PCN10H21020250617111214 | V16: Process change, Site change, Material change, Design change;Qualification of new Fab site (CFAB) using qualified Process Technology, Die Revision, Probe site, and additional Assembly site/BOM options for select devices | W16: 1 2540794008 ISO6741FDWR 2 2540796708 ISO6742FDWR 3 2542001208 ISO6742DWR 4 2542002908 ISO6731FDWR 5 2542009908 ISO6740FDWR | X16: 20221216012.1 | Y16: =VLOOKUP(D:D,Sheet1!A:D,4,FALSE) -> #N/A
A17: LM293ADGKR | B17: RAINIE | C17: 2520090914 | D17: =VLOOKUP(C17,工作表2!A:C,3,0) -> LM293ADGKR | H17: =VLOOKUP(D:D,[1]results!$A:$AE,31,FALSE) -> LAMPS-LVAC | J17: 285 | N17: 285 | O17: Y | P17: PCN10H21020241115051452 PCN10H21020241104115853 | Q17: 2 | R17: Y | S17: Y | T17: PCN10H21020241115051452 PCN10H21020241104115853 | U17: PCN10H21020241115051452 PCN10H21020241104115853 | V17: PCN10H21020241115051452:Design change;Qualification of new Fab site (CFAB) using qualified Process Technology, Die Revision, updated BOMs, and additional Assembly options for select devices PCN10H21020241104115853:Process change, Site change, Material change, Design change;Qualification of RFAB using qualified Process Technology, Die Change, Assembly site (MLA) change & BOM update for select devices | W17: 1 2540794008 ISO6741FDWR 2 2540796708 ISO6742FDWR 3 2542001208 ISO6742DWR 4 2542002908 ISO6731FDWR 5 2542009908 ISO6740FDWR | X17: 20221216012.1 | Y17: =VLOOKUP(D:D,Sheet1!A:D,4,FALSE) -> #N/A
A18: LMV324IPWR | B18: DAISY | C18: 2520017114 | D18: =VLOOKUP(C18,工作表2!A:C,3,0) -> LMV324IPWR | H18: =VLOOKUP(D:D,[1]results!$A:$AE,31,FALSE) -> LAMPS-LVAC | J18: 28000 | N18: 28000 | O18: Y | P18: PCN10H21020250226033253 PCN10H21020241128062552 PCN10H21020230203040806 | Q18: 3 | R18: N | S18: Y | U18: PCN10H21020230203040806 | V18: PCN10H21020250226033253:Process change, Site change, Material change;Qualification of additional Assembly sites for select TSSOP devices PCN10H21020241128062552:Process change;TSSOP and SOT Symbolization update for select devices PCN10H21020230203040806:Site change;Qualification of new Fab site (RFAB) using qualified Process Technology, Die Revision | W18: 1 2520031014 TL084CDR 2 2520031114 TL084CN 3 2520031414 TL084ACDR 4 2520038114 TL072CP 5 2520047114 TL074CN | X18: 20221219006.1 | Y18: =VLOOKUP(D:D,Sheet1!A:D,4,FALSE) -> #N/A
A19: TPS74801DRCR | B19: DAISY | C19: 2500496314 | D19: =VLOOKUP(C19,工作表2!A:C,3,0) -> TPS74801DRCR | H19: =VLOOKUP(D:D,[1]results!$A:$AE,31,FALSE) -> LP-LVL | J19: 21000 | M19: 6000 | N19: 27000 | O19: Y | P19: PCN10H21020240402104959 PCN10H21020231102093137 | Q19: 2 | R19: N | S19: Y | U19: PCN10H21020231102093137 | V19: PCN10H21020240402104959:Material change;Qualify New Assembly Material set PCN10H21020231102093137:Site change;Qualification of new Fab site (RFAB) using qualified Process Technology, Die Revision and additional Assembly Site/BOM options for select devices | W19: 1 2520031014 TL084CDR 2 2520031114 TL084CN 3 2520031414 TL084ACDR 4 2520038114 TL072CP 5 2520047114 TL074CN | X19: 20221219006.1 | Y19: =VLOOKUP(D:D,Sheet1!A:D,4,FALSE) -> #N/A
A20: TPS73701DRBR | B20: DAISY | C20: 2500375414 | D20: =VLOOKUP(C20,工作表2!A:C,3,0) -> TPS73701DRBR | H20: =VLOOKUP(D:D,[1]results!$A:$AE,31,FALSE) -> LP-LVL | J20: 27000 | N20: 27000 | O20: Y | P20: PCN10H21020241203053407 PCN10H21020240228111535 | Q20: 2 | R20: Y | S20: Y | T20: PCN10H21020241203053407 PCN10H21020240228111535 | U20: PCN10H21020240228111535 | V20: PCN10H21020241203053407:Process change;Datasheet for TPS737 PCN10H21020240228111535:Process change, Site change, Material change, Design change | W20: 1 2520031014 TL084CDR 2 2520031114 TL084CN 3 2520031414 TL084ACDR 4 2520038114 TL072CP 5 2520047114 TL074CN | X20: 20221219006.1 | Y20: =VLOOKUP(D:D,Sheet1!A:D,4,FALSE) -> #N/A
A21: ISO1050DWR | B21: DAISY | C21: 2540731408 | D21: =VLOOKUP(C21,工作表2!A:C,3,0) -> ISO1050DWR | H21: =VLOOKUP(D:D,[1]results!$A:$AE,31,FALSE) -> INT-ISO | M21: 26000 | N21: 26000 | O21: Y | P21: PCN10H21020241212025542 PCN10H21020241212030645 PCN10H21020231220112656 PCN10H21020230605032447 | Q21: 4 | R21: N | S21: Y | U21: PCN10H21020241212025542 PCN10H21020241212030645 PCN10H21020231220112656 | V21: PCN10H21020241212025542 Qualification of RFAB using qualified Process Technology, Die Revision, Datasheet and additional Assembly site/BOM options for select devices(group1) PCN10H21020241212030645 Qualification of RFAB using qualified Process Technology, Die Revision, Datasheet and additional Assembly site/BOM options for select devices(group2) PCN10H21020231220112656:Site change;Qualification of RFAB using qualified Process Technology, Die Revision, Datasheet and additional Assembly site/BOM options for select devices PCN10H21020230605032447:Material change;ualify New Assembly Material set for Selected Device(s) | W21: 1 2520031214 TL084IDR 2 2520047014 TL074CDR 3 2520047214 TL074IDR 4 2520048114 LF347N | X21: 20221219006.1(1) | Y21: =VLOOKUP(D:D,Sheet1!A:D,4,FALSE) -> #N/A
A22: SN65HVD3082EDR | B22: CHUNHUA | C22: 2540454908 | D22: =VLOOKUP(C22,工作表2!A:C,3,0) -> SN65HVD3082EDR | H22: =VLOOKUP(D:D,[1]results!$A:$AE,31,FALSE) -> INT-TRX | J22: 872500 | L22: 10000 | M22: 40500 | N22: 923000 | O22: Y | P22: PCN10H21020250915125042 PCN10H21020241118085631 | Q22: 2 | R22: Y | S22: Y | U22: PCN10H21020250915125042 | V22: Process change, Site change, Material change, Design change | W22: 1 250005001 LM4040DIM3X-2.5/NOPB 2 250005031 LM4040C50IDBZR 3 2500050311 LM4040CIM3X-5.0/NOPB 4 2500050411 LM4040BIM3-2.5/NOPB 5 2500050511 LM4040BIM3-5.0/NOPB 6 250005081 LM4040C25IDBZR 7 2500050814M LM4040C25QDBZR 8 2500323214 LM4040B41IDBZR 9 2500323811 LM4040AIM3-3.0/NOPB 10 2500323814 LM4040A30IDBZR 11 2500379114 LM4040B50IDBZR 12 2500379511 LM4040BIM3X-3.0/NOPB 13 2500379614 LM4040D41IDBZR 14 250044611 LM4041C12QDBZR 15 2500459314 LM4040C50QDBZR 16 2500459514 LM4040C20QDBZR 17 2500459814 LM4040DIM3X-3.0/NOPB 18 2500459914 LM4040DIM3X-5.0/NOPB 19 2500549114 LM4040D30IDBZR 20 2500549214 LM4040D50IDBZR | X22: 20230228000.1 | Y22: YES
A23: THVD1520DR | B23: CHUNHUA | C23: 2540773508 | D23: =VLOOKUP(C23,工作表2!A:C,3,0) -> THVD1520DR | H23: =VLOOKUP(D:D,[1]results!$A:$AE,31,FALSE) -> INT-TRX | J23: 635000 | L23: 82500 | N23: 717500 | O23: Y | P23: PCN10H21020241118085631 PCN10H21020241008041320 | Q23: 2 | R23: Y | S23: Y | U23: PCN10H21020241008041320 | V23: Qualification of new Fab site (RFAB) using qualified Process Technology, Die Revision and additional BOM elements for select devices | W23: 1 250005001 LM4040DIM3X-2.5/NOPB 2 250005031 LM4040C50IDBZR 3 2500050311 LM4040CIM3X-5.0/NOPB 4 2500050411 LM4040BIM3-2.5/NOPB 5 2500050511 LM4040BIM3-5.0/NOPB 6 250005081 LM4040C25IDBZR 7 2500050814M LM4040C25QDBZR 8 2500323214 LM4040B41IDBZR 9 2500323811 LM4040AIM3-3.0/NOPB 10 2500323814 LM4040A30IDBZR 11 2500379114 LM4040B50IDBZR 12 2500379511 LM4040BIM3X-3.0/NOPB 13 2500379614 LM4040D41IDBZR 14 250044611 LM4041C12QDBZR 15 2500459314 LM4040C50QDBZR 16 2500459514 LM4040C20QDBZR 17 2500459814 LM4040DIM3X-3.0/NOPB 18 2500459914 LM4040DIM3X-5.0/NOPB 19 2500549114 LM4040D30IDBZR 20 2500549214 LM4040D50IDBZR | X23: 20230228000.1 | Y23: YES
A24: SN74LVC244APWR | B24: CHUNHUA | C24: 2600116608 | D24: =VLOOKUP(C24,工作表2!A:C,3,0) -> SN74LVC244APWR | H24: =VLOOKUP(D:D,[1]results!$A:$AE,31,FALSE) -> INT-LOGIC | J24: 622000 | N24: 622000 | O24: Y | P24: PCN10H21020251030101724 | Q24: 1 | R24: Y | S24: Y | U24: PCN10H21020251030101724 | V24: Process change, Site change, Material change, Design change Qualification of RFAB as an additional Fab site, Die Revision and BOM option for select devices | W24: 1 250005001 LM4040DIM3X-2.5/NOPB 2 250005031 LM4040C50IDBZR 3 2500050311 LM4040CIM3X-5.0/NOPB 4 2500050411 LM4040BIM3-2.5/NOPB 5 2500050511 LM4040BIM3-5.0/NOPB 6 250005081 LM4040C25IDBZR 7 2500050814M LM4040C25QDBZR 8 2500323214 LM4040B41IDBZR 9 2500323811 LM4040AIM3-3.0/NOPB 10 2500323814 LM4040A30IDBZR 11 2500379114 LM4040B50IDBZR 12 2500379511 LM4040BIM3X-3.0/NOPB 13 2500379614 LM4040D41IDBZR 14 250044611 LM4041C12QDBZR 15 2500459314 LM4040C50QDBZR 16 2500459514 LM4040C20QDBZR 17 2500459814 LM4040DIM3X-3.0/NOPB 18 2500459914 LM4040DIM3X-5.0/NOPB 19 2500549114 LM4040D30IDBZR 20 2500549214 LM4040D50IDBZR | X24: 20230228000.1 | Y24: YES
A25: LM2902PWR | B25: CHUNHUA | C25: 2520036314 | D25: =VLOOKUP(C25,工作表2!A:C,3,0) -> LM2902PWR | F25: 2526+5 | G25: 45880 | H25: =VLOOKUP(D:D,[1]results!$A:$AE,31,FALSE) -> LAMPS-HVA | L25: 212000 | N25: 212000 | O25: Y | P25: PCN10H21020250106035330 PCN10H21020241231051413 PCN10H21020241231050033 PCN10H21020241231044210 PCN10H21020241128062552 | Q25: 5 | R25: N | S25: Y | U25: PCN10H21020241128062552 | V25: Process change, Site change, Material change, Design change Qualification of RFAB using qualified Process Technology, Die Revision, Assembly site (MLA & FMX) & alternate BOM qualification for select devices(group1) | W25: 1 250005001 LM4040DIM3X-2.5/NOPB 2 250005031 LM4040C50IDBZR 3 2500050311 LM4040CIM3X-5.0/NOPB 4 2500050411 LM4040BIM3-2.5/NOPB 5 2500050511 LM4040BIM3-5.0/NOPB 6 250005081 LM4040C25IDBZR 7 2500050814M LM4040C25QDBZR 8 2500323214 LM4040B41IDBZR 9 2500323811 LM4040AIM3-3.0/NOPB 10 2500323814 LM4040A30IDBZR 11 2500379114 LM4040B50IDBZR 12 2500379511 LM4040BIM3X-3.0/NOPB 13 2500379614 LM4040D41IDBZR 14 250044611 LM4041C12QDBZR 15 2500459314 LM4040C50QDBZR 16 2500459514 LM4040C20QDBZR 17 2500459814 LM4040DIM3X-3.0/NOPB 18 2500459914 LM4040DIM3X-5.0/NOPB 19 2500549114 LM4040D30IDBZR 20 2500549214 LM4040D50IDBZR | X25: 20230228000.1 | Y25: YES
A26: MC33063AQDRQ1 | B26: CHUNHUA | C26: 2540486208 | D26: =VLOOKUP(C26,工作表2!A:C,3,0) -> MC33063AQDRQ1 | H26: =VLOOKUP(D:D,[1]results!$A:$AE,31,FALSE) -> SR-BCC | J26: 197500 | L26: 2500 | N26: 200000 | O26: Y | P26: PCN10H21020250917164517 PCN10H21020250402115149 PCN10H21020241118085631 PCN10H21020240304113816 | Q26: 4 | R26: N | S26: Y | U26: PCN10H21020250917164517 | V26: Process change, Site change, Material change, Design change Qualification of new Fab site (RFAB) using qualified Process Technology, Die Revision and TI CDAT-PR as additional wafer probe (EWS) site for select devices | W26: 1 250005001 LM4040DIM3X-2.5/NOPB 2 250005031 LM4040C50IDBZR 3 2500050311 LM4040CIM3X-5.0/NOPB 4 2500050411 LM4040BIM3-2.5/NOPB 5 2500050511 LM4040BIM3-5.0/NOPB 6 250005081 LM4040C25IDBZR 7 2500050814M LM4040C25QDBZR 8 2500323214 LM4040B41IDBZR 9 2500323811 LM4040AIM3-3.0/NOPB 10 2500323814 LM4040A30IDBZR 11 2500379114 LM4040B50IDBZR 12 2500379511 LM4040BIM3X-3.0/NOPB 13 2500379614 LM4040D41IDBZR 14 250044611 LM4041C12QDBZR 15 2500459314 LM4040C50QDBZR 16 2500459514 LM4040C20QDBZR 17 2500459814 LM4040DIM3X-3.0/NOPB 18 2500459914 LM4040DIM3X-5.0/NOPB 19 2500549114 LM4040D30IDBZR 20 2500549214 LM4040D50IDBZR | X26: 20230228000.1 | Y26: YES
A27: NE555DR | B27: CHUNHUA | C27: 2510003214 | D27: =VLOOKUP(C27,工作表2!A:C,3,0) -> NE555DR | H27: =VLOOKUP(D:D,[1]results!$A:$AE,31,FALSE) -> LAMPS-LVAC | L27: 75000 | M27: 90000 | N27: 165000 | O27: Y | P27: PCN10H21020251219103343 PCN10H21020241202012940 PCN10H21020241118085631 PCN10H21020241008041320 | Q27: 4 | R27: N | S27: Y | U27: PCN10H21020241008041320 PCN10H21020251219103343 | V27: Qualification of new Fab site (RFAB) using qualified Process Technology, Die Revision and additional BOM elements for select devices | W27: 1 250005001 LM4040DIM3X-2.5/NOPB 2 250005031 LM4040C50IDBZR 3 2500050311 LM4040CIM3X-5.0/NOPB 4 2500050411 LM4040BIM3-2.5/NOPB 5 2500050511 LM4040BIM3-5.0/NOPB 6 250005081 LM4040C25IDBZR 7 2500050814M LM4040C25QDBZR 8 2500323214 LM4040B41IDBZR 9 2500323811 LM4040AIM3-3.0/NOPB 10 2500323814 LM4040A30IDBZR 11 2500379114 LM4040B50IDBZR 12 2500379511 LM4040BIM3X-3.0/NOPB 13 2500379614 LM4040D41IDBZR 14 250044611 LM4041C12QDBZR 15 2500459314 LM4040C50QDBZR 16 2500459514 LM4040C20QDBZR 17 2500459814 LM4040DIM3X-3.0/NOPB 18 2500459914 LM4040DIM3X-5.0/NOPB 19 2500549114 LM4040D30IDBZR 20 2500549214 LM4040D50IDBZR | X27: 20230228000.1 | Y27: YES
A28: LM293DR | B28: CHUNHUA | C28: 2520090014 | D28: =VLOOKUP(C28,工作表2!A:C,3,0) -> LM293DR | H28: =VLOOKUP(D:D,[1]results!$A:$AE,31,FALSE) -> LAMPS-LVAC | J28: 65000 | L28: 5000 | M28: 90000 | N28: 160000 | O28: Y | P28: PCN10H21020250307103025 PCN10H21020241118085631 PCN10H21020241008041320 PCN10H21020240410112100 | Q28: 4 | R28: N | S28: Y | U28: PCN10H21020241008041320 | V28: Qualification of new Fab site (RFAB) using qualified Process Technology, Die Revision and additional BOM elements for select devices | W28: 1 250005001 LM4040DIM3X-2.5/NOPB 2 250005031 LM4040C50IDBZR 3 2500050311 LM4040CIM3X-5.0/NOPB 4 2500050411 LM4040BIM3-2.5/NOPB 5 2500050511 LM4040BIM3-5.0/NOPB 6 250005081 LM4040C25IDBZR 7 2500050814M LM4040C25QDBZR 8 2500323214 LM4040B41IDBZR 9 2500323811 LM4040AIM3-3.0/NOPB 10 2500323814 LM4040A30IDBZR 11 2500379114 LM4040B50IDBZR 12 2500379511 LM4040BIM3X-3.0/NOPB 13 2500379614 LM4040D41IDBZR 14 250044611 LM4041C12QDBZR 15 2500459314 LM4040C50QDBZR 16 2500459514 LM4040C20QDBZR 17 2500459814 LM4040DIM3X-3.0/NOPB 18 2500459914 LM4040DIM3X-5.0/NOPB 19 2500549114 LM4040D30IDBZR 20 2500549214 LM4040D50IDBZR | X28: 20230228000.1 | Y28: YES
A29: SN74ACT240PWR | B29: CHUNHUA | C29: 2600212208 | D29: =VLOOKUP(C29,工作表2!A:C,3,0) -> SN74ACT240PWR | F29: 2502+5 | G29: 45681 | H29: =VLOOKUP(D:D,[1]results!$A:$AE,31,FALSE) -> INT-LOGIC | J29: 156000 | N29: 156000 | O29: Y | P29: PCN10H21020250410122453 PCN10H21020241203044507 PCN10H21020240226113556 | Q29: 3 | R29: N | S29: Y | U29: PCN10H21020250410122453 | V29: Process change, Site change, Material change, Design change Qualification of additional Fab site (RFAB) using qualified Process Technology and additional Assembly Site/BOM options for select devices(group6) | W29: 1 250005001 LM4040DIM3X-2.5/NOPB 2 250005031 LM4040C50IDBZR 3 2500050311 LM4040CIM3X-5.0/NOPB 4 2500050411 LM4040BIM3-2.5/NOPB 5 2500050511 LM4040BIM3-5.0/NOPB 6 250005081 LM4040C25IDBZR 7 2500050814M LM4040C25QDBZR 8 2500323214 LM4040B41IDBZR 9 2500323811 LM4040AIM3-3.0/NOPB 10 2500323814 LM4040A30IDBZR 11 2500379114 LM4040B50IDBZR 12 2500379511 LM4040BIM3X-3.0/NOPB 13 2500379614 LM4040D41IDBZR 14 250044611 LM4041C12QDBZR 15 2500459314 LM4040C50QDBZR 16 2500459514 LM4040C20QDBZR 17 2500459814 LM4040DIM3X-3.0/NOPB 18 2500459914 LM4040DIM3X-5.0/NOPB 19 2500549114 LM4040D30IDBZR 20 2500549214 LM4040D50IDBZR | X29: 20230228000.1 | Y29: YES
A30: UCC27424DGNR | B30: DAISY | C30: 2540394708 | D30: =VLOOKUP(C30,工作表2!A:C,3,0) -> UCC27424DGNR | H30: =VLOOKUP(D:D,[1]results!$A:$AE,31,FALSE) -> HVP-DBB | L30: 31500 | N30: 31500 | O30: Y | P30: PCN10H21020240221114349 | R30: Y | S30: Y | T30: PCN10H21020240221114349 | U30: PCN10H21020240221114349 | V30: PCN10H21020240221114349:Process change, Site change, Material change, Design change;Qualification of RFAB using qualified Process Technology, Die Revision, Datasheet, and additional Assembly site/BOM options for select devices | Y30: =VLOOKUP(D:D,Sheet1!A:D,4,FALSE) -> #N/A
A31: MC3303DR | B31: CHUNHUA | C31: 2520044014 | D31: =VLOOKUP(C31,工作表2!A:C,3,0) -> MC3303DR | F31: 2532+5 | G31: 45962 | H31: =VLOOKUP(D:D,[1]results!$A:$AE,31,FALSE) -> LAMPS-HVA | J31: 120000 | N31: 120000 | O31: Y | P31: PCN10H21020250106040435 PCN10H21020241231051413 PCN10H21020241231050033 PCN10H21020241231044210 PCN10H21020241118085631 | Q31: 5 | R31: N | S31: Y | T31: 否 | U31: PCN10H21020250106040435 | V31: Process change, Site change, Material change, Design change Qualification of RFAB using qualified Process Technology, Die Revision, Assembly site (MLA & FMX) & alternate BOM qualification for select devices(group4) | W31: 1 250005001 LM4040DIM3X-2.5/NOPB 2 250005031 LM4040C50IDBZR 3 2500050311 LM4040CIM3X-5.0/NOPB 4 2500050411 LM4040BIM3-2.5/NOPB 5 2500050511 LM4040BIM3-5.0/NOPB 6 250005081 LM4040C25IDBZR 7 2500050814M LM4040C25QDBZR 8 2500323214 LM4040B41IDBZR 9 2500323811 LM4040AIM3-3.0/NOPB 10 2500323814 LM4040A30IDBZR 11 2500379114 LM4040B50IDBZR 12 2500379511 LM4040BIM3X-3.0/NOPB 13 2500379614 LM4040D41IDBZR 14 250044611 LM4041C12QDBZR 15 2500459314 LM4040C50QDBZR 16 2500459514 LM4040C20QDBZR 17 2500459814 LM4040DIM3X-3.0/NOPB 18 2500459914 LM4040DIM3X-5.0/NOPB 19 2500549114 LM4040D30IDBZR 20 2500549214 LM4040D50IDBZR | X31: 20230228000.1 | Y31: YES
A32: SN74ACT244PWR | B32: CHUNHUA | C32: 2600354008 | D32: =VLOOKUP(C32,工作表2!A:C,3,0) -> SN74ACT244PWR | H32: =VLOOKUP(D:D,[1]results!$A:$AE,31,FALSE) -> INT-LOGIC | M32: 116000 | N32: 116000 | O32: Y | P32: PCN10H21020241203044507 PCN10H21020240410120554 | Q32: 2 | R32: N | S32: Y | U32: PCN10H21020240410120554 | V32: Qualification of RFAB using qualified Process Technology, Die Change, and additional Assembly site & BOM options | W32: 1 250005001 LM4040DIM3X-2.5/NOPB 2 250005031 LM4040C50IDBZR 3 2500050311 LM4040CIM3X-5.0/NOPB 4 2500050411 LM4040BIM3-2.5/NOPB 5 2500050511 LM4040BIM3-5.0/NOPB 6 250005081 LM4040C25IDBZR 7 2500050814M LM4040C25QDBZR 8 2500323214 LM4040B41IDBZR 9 2500323811 LM4040AIM3-3.0/NOPB 10 2500323814 LM4040A30IDBZR 11 2500379114 LM4040B50IDBZR 12 2500379511 LM4040BIM3X-3.0/NOPB 13 2500379614 LM4040D41IDBZR 14 250044611 LM4041C12QDBZR 15 2500459314 LM4040C50QDBZR 16 2500459514 LM4040C20QDBZR 17 2500459814 LM4040DIM3X-3.0/NOPB 18 2500459914 LM4040DIM3X-5.0/NOPB 19 2500549114 LM4040D30IDBZR 20 2500549214 LM4040D50IDBZR | X32: 20230228000.1 | Y32: =VLOOKUP(D:D,Sheet1!A:D,4,FALSE) -> YES
A33: ISO6720FBDR | B33: DAISY | C33: 2542024208 | D33: =VLOOKUP(C33,工作表2!A:C,3,0) -> ISO6720FBDR | F33: 2401+5 | G33: 45584 | H33: =VLOOKUP(D:D,[1]results!$A:$AE,31,FALSE) -> INT-ISO | L33: 24000 | N33: 24000 | O33: Y | P33: PCN10H21020240809031513 PCN10H21020230310110902 PCN10H21020230210034659 | Q33: 3 | R33: Y | S33: Y | T33: PCN10H21020230310110902 | U33: PCN10H21020230310110902 PCN10H21020230210034659 | V33: PCN10H21020240809031513:Process change, Material change;Add Cu as Alternative Wire Base Metal for Selected Device(s) PCN10H21020230310110902:Design change;Datasheet for ISO672x PCN10H21020230210034659:Site change,Process change;Qualification of RFAB as an additional Fab site option for select LBC8 devices | W33: 1 2520063141 OPA2277UA/2K5 | X33: 20230228008.1 | Y33: =VLOOKUP(D:D,Sheet1!A:D,4,FALSE) -> #N/A
A34: LP2985-33DBVR | B34: JINGJING | C34: 2500235014 | D34: =VLOOKUP(C34,工作表2!A:C,3,0) -> LP2985-33DBVR | H34: =VLOOKUP(D:D,[1]results!$A:$AE,31,FALSE) -> LP-MWL | L34: 6000 | N34: 6000 | O34: Y | P34: PCN10H21020240911110514 PCN10H21020240923100040 PCN10H21020241209052044 PCN10H21020250506044328 PCN10H21020250926113837 | Q34: 5 | R34: Y | S34: Y | T34: PCN10H21020240911110514 | U34: PCN10H21020240911110514 | V34: PCN10H21020240911110514:Process change, Site change, Material change, Design change;Qualification of RFAB Wafer Fab site using qualified Process Technology, Die Revision and additional Assembly site/BOM options for select devices PCN10H21020250506044328:Process change:Pin one Device symbolization update for Select SOT Devices PCN10H21020241209052044:Process change;Pin one Device symbolization update for Select SOT Devices | W34: 1 2520121314M TLC2272AQPWRQ1 2 2520121414M TLC2274AQPWRQ1 3 2520201614M TLV2374QPWRG4Q1 4 2520270814M TLV272QDRQ1 5 2520277114M TLV2474APWPRQ1 6 2540485008M TRS3232EQPWRQ1 | X34: 20230306002.2 | Y34: =VLOOKUP(D:D,Sheet1!A:D,4,FALSE) -> #N/A
A35: CD4504BM96 | B35: YUHUA | C35: 2600255008 | D35: =VLOOKUP(C35,工作表2!A:C,3,0) -> CD4504BM96 | H35: =VLOOKUP(D:D,[1]results!$A:$AE,31,FALSE) -> INT-TXP | O35: Y | P35: PCN10H21020250317102220 PCN10H21020241118085631 PCN10H21020241115051403 PCN10H21020240627032733 | Q35: 4 | R35: Y | S35: Y | T35: PCN10H21020250317102220 | U35: PCN10H21020241115051403 | V35: PCN10H21020250317102220 Datasheet for SNx4ACT74, SNx4AC74, SNx4ACT00, SNx4AC00, SNx4ACT10, SNx4AC32, SNx4AC10, SN74ACT32, SNx4ACT11, SNx4AC11, SNx4AC86, SNx4ACT86, SNx4ACT08, SNx4AC08, SN74ACT10-Q1, SN74AC08-Q1, CDx4AC74, CD74AC251, CDx4AC257, CDx4ACT257, CD74ACT258. CDx4AC00, CDx4AC02, CDx4AC08, CDx4ACT00, CDx4ACT08, CDx4ACT74, CD74AC151, CDx4AC153, CDx4ACT151, CD74ACT157, CDx4ACT322, CDx4AC32 PCN10H21020241115051403 Qualification of RFAB using qualified Process Technology, Die Change, and additional Assembly site & BOM options(Group 5 | W35: 1 2600368308 SN74LV06ADR 2 2600515008 SN74LV367ADR | X35: 20230327003.1 | Y35: =VLOOKUP(D:D,Sheet1!A:D,4,FALSE) -> #N/A
A36: TLVH431BQDBZR | B36: CHUNHUA | C36: 2500434214 | D36: =VLOOKUP(C36,工作表2!A:C,3,0) -> TLVH431BQDBZR | H36: =VLOOKUP(D:D,[1]results!$A:$AE,31,FALSE) -> LP-VRS | L36: 54000 | M36: 10 | N36: 54010 | O36: Y | P36: PCN10H21020250506044328 PCN10H21020241209052044 PCN10H21020240208110646 | Q36: 3 | R36: N | S36: Y | U36: PCN10H21020240208110646 | V36: reject | W36: 1 2510400314 TPS40057PWPR | X36: 20230522004.1 | Y36: =VLOOKUP(D:D,Sheet1!A:D,4,FALSE) -> #N/A
A37: LM2903BIDGKR | B37: CHUNHUA | C37: 2522019014 | D37: =VLOOKUP(C37,工作表2!A:C,3,0) -> LM2903BIDGKR | H37: =VLOOKUP(D:D,[1]results!$A:$AE,31,FALSE) -> LAMPS-LVAC | L37: 115000 | N37: 115000 | O37: Y | P37: PCN10H21020250307103025 PCN10H21020250303045956 PCN10H21020241104115853 PCN10H21020240529021730 | Q37: 4 | R37: Y | S37: Y | T37: PCN10H21020241104115853 | U37: PCN10H21020241104115853 | V37: Qualification of RFAB using qualified Process Technology, Die Change, Assembly site (MLA) change & BOM update for select devices | W37: 1 2500466214M TLV70033QDDCRQ1 2 2500466314M TLV70012QDDCRQ1 3 2510762914M TPS62130AQRGTRQ1 4 25107629GL9 TPS62130AQRGTRQ1 5 2510770214M TPS62160QDSGRQ1 6 2510798714M TPS62162QDSGRQ1 | X37: 20230523000.2 | Y37: =VLOOKUP(D:D,Sheet1!A:D,4,FALSE) -> #N/A
A38: SN74CB3T3245PWR | B38: YUHUA | C38: 2600141308 | D38: =VLOOKUP(C38,工作表2!A:C,3,0) -> SN74CB3T3245PWR | H38: =VLOOKUP(D:D,[1]results!$A:$AE,31,FALSE) -> INT-MUX | O38: Y | P38: PCN10H21020250317102220 PCN10H21020250108043635 PCN10H21020241128062552 PCN10H21020241115050920 PCN10H21020240627032733 | Q38: 5 | R38: Y | S38: Y | T38: PCN10H21020250317102220 | U38: PCN10H21020250108043635 | V38: PCN10H21020250317102220 Datasheet for SNx4ACT74, SNx4AC74, SNx4ACT00, SNx4AC00, SNx4ACT10, SNx4AC32, SNx4AC10, SN74ACT32, SNx4ACT11, SNx4AC11, SNx4AC86, SNx4ACT86, SNx4ACT08, SNx4AC08, SN74ACT10-Q1, SN74AC08-Q1, CDx4AC74, CD74AC251, CDx4AC257, CDx4ACT257, CD74ACT258. CDx4AC00, CDx4AC02, CDx4AC08, CDx4ACT00, CDx4ACT08, CDx4ACT74, CD74AC151, CDx4AC153, CDx4ACT151, CD74ACT157, CDx4ACT322, CDx4AC32 PCN10H21020250108043635 Qualification of NFME as an additional assembly site for select devices | W38: 1 2610965208M TMS320F28075PZPQ 2 2610965708M TMS320F28075PTPQ 3 2611305108M TMS320F28377DPTPQ | X38: 20230620000.2 | Y38: =VLOOKUP(D:D,Sheet1!A:D,4,FALSE) -> #N/A
A39: LP2951ACMX/NOPB | B39: DAISY | C39: 2500102111 | D39: =VLOOKUP(C39,工作表2!A:C,3,0) -> LP2951ACMX/NOPB | H39: =VLOOKUP(D:D,[1]results!$A:$AE,31,FALSE) -> LP-MWL | J39: 2500 | L39: 30000 | N39: 32500 | O39: Y | P39: PCN10016820180212043347 PCN10005420170103101430 PCN10005420140418093459 | Q39: 3 | R39: Y | S39: N | T39: PCN10016820180212043347 | V39: PCN10016820180212043347:Process change:Notification# 20180110002 Datasheet for LP2950-N, LP2951-N Information Only PCN10005420170103101430:Material change:Qualification of SID# 101380756 Mold Compound for Select SOIC Device(s) PCN10005420140418093459:Material change;Final notification of Qualification of TI Mexico as an Additional Assembly site for Pb Free/ Green UCC devices in SOIC D Packages | W39: 1 2510003214 NE555DR 2 2520012114 LM2903DR 3 2520019014 LM2904DR 4 2520085014 LM258DR 5 2520085214 LM258ADR 6 2520090014 LM293DR 7 2520125014 LM211DR 8 2522012014 OPA2607IDR 9 2540605108 UCC27525D 10 2540773508 THVD1520DR | X39: 20230627002.1 | Y39: =VLOOKUP(D:D,Sheet1!A:D,4,FALSE) -> #N/A
A40: UC2845AQD8R | B40: DAISY | C40: 2510237814M | D40: =VLOOKUP(C40,工作表2!A:C,3,0) -> UC2845AQD8R | H40: =VLOOKUP(D:D,[1]results!$A:$AE,31,FALSE) -> HVP-ACDC | L40: 29500 | N40: 29500 | O40: Y | P40: PCN10H21020250411032907 PCN10H21020250314053135 PCN10H21020241118085631 | Q40: 3 | R40: Y | S40: Y | T40: PCN10H21020250314053135 | U40: PCN10H21020250411032907 | V40: PCN10H21020250411032907:Qualification of RFAB using qualified Process Technology & Die Change PCN10H21020250314053135:Datasheet for UC2842AQ, UC2843AQ, UC2844AQ, UC2845AQ, UC2843A-Q1 PCN10H21020241118085631:MARKING | W40: 1 2510003214 NE555DR 2 2520012114 LM2903DR 3 2520019014 LM2904DR 4 2520085014 LM258DR 5 2520085214 LM258ADR 6 2520090014 LM293DR 7 2520125014 LM211DR 8 2522012014 OPA2607IDR 9 2540605108 UCC27525D 10 2540773508 THVD1520DR | X40: 20230627002.1 | Y40: =VLOOKUP(D:D,Sheet1!A:D,4,FALSE) -> #N/A
...
